<?xml version="1.0" encoding="utf-8"?>
<!-- This URDF was automatically created by SolidWorks to URDF Exporter! Originally created by Stephen Brawner (brawner@gmail.com) 
     Commit Version: 1.6.0-4-g7f85cfe  Build Version: 1.6.7995.38578
     For more information, please see http://wiki.ros.org/sw_urdf_exporter -->
<robot
  name="jaka_pro18">

  <!-- LINK -->
  <link name="world" />

  <link
    name="base_link">
    <inertial>
      <origin
        xyz="0.0016792 2.2339E-05 0.020196"
        rpy="0 0 0" />
      <mass
        value="0.82831" />
      <inertia
        ixx="0.0016621"
        ixy="6.7056E-07"
        ixz="6.8687E-06"
        iyy="0.0020138"
        iyz="4.9893E-07"
        izz="0.0034826" />
    </inertial>
    <visual>
      <origin
        xyz="0 0 0"
        rpy="0 0 0" />
      <geometry>
        <mesh
          filename="package://jaka_description/meshes/jaka_pro18_meshes/base_link.STL" />
      </geometry>
      <material
        name="">
        <color
          rgba="0.79216 0.81961 0.93333 1" />
      </material>
    </visual>
    <collision>
      <origin
        xyz="0 0 0"
        rpy="0 0 0" />
      <geometry>
        <mesh
          filename="package://jaka_description/meshes/jaka_pro18_meshes/base_link.STL" />
      </geometry>
    </collision>
  </link>

  <joint name="fixed" type="fixed">
    <origin xyz="0 0 0" rpy="0 0 0" />
     <parent link="world"/>
     <child link="base_link"/>
  </joint>

  <link
    name="Link_01">
    <inertial>
      <origin
        xyz="-1.348E-07 0.0039698 -0.0033275"
        rpy="0 0 0" />
      <mass
        value="29.677" />
      <inertia
        ixx="0.13784"
        ixy="1.785E-07"
        ixz="-5.8341E-07"
        iyy="0.1346"
        iyz="-0.00028533"
        izz="0.092584" />
    </inertial>
    <visual>
      <origin
        xyz="0 0 0"
        rpy="0 0 0" />
      <geometry>
        <mesh
          filename="package://jaka_description/meshes/jaka_pro18_meshes/Link_01.STL" />
      </geometry>
      <material
        name="">
        <color
          rgba="0.84706 0.84706 0.84706 1" />
      </material>
    </visual>
    <collision>
      <origin
        xyz="0 0 0"
        rpy="0 0 0" />
      <geometry>
        <mesh
          filename="package://jaka_description/meshes/jaka_pro18_meshes/Link_01.STL" />
      </geometry>
    </collision>
  </link>
  <joint
    name="joint_1"
    type="revolute">
    <origin
      xyz="0 0 0.14265"
      rpy="0 0 0" />
    <parent
      link="base_link" />
    <child
      link="Link_01" />
    <axis
      xyz="0 0 1" />
    <limit
      lower="-6.28"
      upper="6.28"
      effort="2000"
      velocity="2.09" />
  </joint>
  <link
    name="Link_02">
    <inertial>
      <origin
        xyz="0.20686 3.4512E-07 -0.18004"
        rpy="0 0 0" />
      <mass
        value="76.064" />
      <inertia
        ixx="0.2333"
        ixy="1.612E-06"
        ixz="0.013448"
        iyy="3.2427"
        iyz="1.1055E-07"
        izz="3.1836" />
    </inertial>
    <visual>
      <origin
        xyz="0 0 0"
        rpy="0 0 0" />
      <geometry>
        <mesh
          filename="package://jaka_description/meshes/jaka_pro18_meshes/Link_02.STL" />
      </geometry>
      <material
        name="">
        <color
          rgba="0.84706 0.84706 0.84706 1" />
      </material>
    </visual>
    <collision>
      <origin
        xyz="0 0 0"
        rpy="0 0 0" />
      <geometry>
        <mesh
          filename="package://jaka_description/meshes/jaka_pro18_meshes/Link_02.STL" />
      </geometry>
    </collision>
  </link>
  <joint
    name="joint_2"
    type="revolute">
    <origin
      xyz="0 0 0"
      rpy="1.5708 0 0" />
    <parent
      link="Link_01" />
    <child
      link="Link_02" />
    <axis
      xyz="0 0 1" />
    <limit
      lower="-1.48"
      upper="4.62"
      effort="8000"
      velocity="2.09" />
  </joint>
  <link
    name="Link_03">
    <inertial>
      <origin
        xyz="0.21141 -5.3417E-08 -0.046049"
        rpy="0 0 0" />
      <mass
        value="24.173" />
      <inertia
        ixx="0.030749"
        ixy="3.263E-07"
        ixz="-0.026498"
        iyy="0.59872"
        iyz="8.6293E-08"
        izz="0.59285" />
    </inertial>
    <visual>
      <origin
        xyz="0 0 0"
        rpy="0 0 0" />
      <geometry>
        <mesh
          filename="package://jaka_description/meshes/jaka_pro18_meshes/Link_03.STL" />
      </geometry>
      <material
        name="">
        <color
          rgba="0.84706 0.84706 0.84706 1" />
      </material>
    </visual>
    <collision>
      <origin
        xyz="0 0 0"
        rpy="0 0 0" />
      <geometry>
        <mesh
          filename="package://jaka_description/meshes/jaka_pro18_meshes/Link_03.STL" />
      </geometry>
    </collision>
  </link>
  <joint
    name="joint_3"
    type="revolute">
    <origin
      xyz="0.51 0 0"
      rpy="0 0 0" />
    <parent
      link="Link_02" />
    <child
      link="Link_03" />
    <axis
      xyz="0 0 1" />
    <limit
      lower="-3.05"
      upper="3.05"
      effort="8000"
      velocity="3.14" />
  </joint>
  <link
    name="Link_04">
    <inertial>
      <origin
        xyz="4.6823E-07 -0.003388 0.0032625"
        rpy="0 0 0" />
      <mass
        value="6.9374" />
      <inertia
        ixx="0.012275"
        ixy="7.981E-09"
        ixz="-1.3755E-08"
        iyy="0.0082652"
        iyz="-7.0839E-05"
        izz="0.011814" />
    </inertial>
    <visual>
      <origin
        xyz="0 0 0"
        rpy="0 0 0" />
      <geometry>
        <mesh
          filename="package://jaka_description/meshes/jaka_pro18_meshes/Link_04.STL" />
      </geometry>
      <material
        name="">
        <color
          rgba="0.84706 0.84706 0.84706 1" />
      </material>
    </visual>
    <collision>
      <origin
        xyz="0 0 0"
        rpy="0 0 0" />
      <geometry>
        <mesh
          filename="package://jaka_description/meshes/jaka_pro18_meshes/Link_04.STL" />
      </geometry>
    </collision>
  </link>
  <joint
    name="joint_4"
    type="revolute">
    <origin
      xyz="0.4 0 -0.154"
      rpy="0 0 0" />
    <parent
      link="Link_03" />
    <child
      link="Link_04" />
    <axis
      xyz="0 0 1" />
    <limit
      lower="-1.48"
      upper="4.62"
      effort="5000"
      velocity="3.14" />
  </joint>
  <link
    name="Link_05">
    <inertial>
      <origin
        xyz="2.2353E-07 -0.0055286 -0.0028281"
        rpy="0 0 0" />
      <mass
        value="1.0195" />
      <inertia
        ixx="0.0022229"
        ixy="-1.0568E-08"
        ixz="6.2513E-09"
        iyy="0.0011893"
        iyz="1.6683E-05"
        izz="0.0021628" />
    </inertial>
    <visual>
      <origin
        xyz="0 0 0"
        rpy="0 0 0" />
      <geometry>
        <mesh
          filename="package://jaka_description/meshes/jaka_pro18_meshes/Link_05.STL" />
      </geometry>
      <material
        name="">
        <color
          rgba="1 1 1 1" />
      </material>
    </visual>
    <collision>
      <origin
        xyz="0 0 0"
        rpy="0 0 0" />
      <geometry>
        <mesh
          filename="package://jaka_description/meshes/jaka_pro18_meshes/Link_05.STL" />
      </geometry>
    </collision>
  </link>
  <joint
    name="joint_5"
    type="revolute">
    <origin
      xyz="0 -0.115 0"
      rpy="1.5708 0 0" />
    <parent
      link="Link_04" />
    <child
      link="Link_05" />
    <axis
      xyz="0 0 1" />
    <limit
      lower="-6.28"
      upper="6.28"
      effort="5000"
      velocity="3.14" />
  </joint>
  <link
    name="Link_06">
    <inertial>
      <origin
        xyz="-0.00023437 0.00011089 -0.021511"
        rpy="0 0 0" />
      <mass
        value="0.2212" />
      <inertia
        ixx="0.00013117"
        ixy="-9.4543E-08"
        ixz="-8.58E-08"
        iyy="0.00013557"
        iyz="4.2774E-09"
        izz="0.00021977" />
    </inertial>
    <visual>
      <origin
        xyz="0 0 0"
        rpy="0 0 0" />
      <geometry>
        <mesh
          filename="package://jaka_description/meshes/jaka_pro18_meshes/Link_06.STL" />
      </geometry>
      <material
        name="">
        <color
          rgba="1 1 1 1" />
      </material>
    </visual>
    <collision>
      <origin
        xyz="0 0 0"
        rpy="0 0 0" />
      <geometry>
        <mesh
          filename="package://jaka_description/meshes/jaka_pro18_meshes/Link_06.STL" />
      </geometry>
    </collision>
  </link>
  <joint
    name="joint_6"
    type="revolute">
    <origin
      xyz="0.00025836 0.1035 0.00025795"
      rpy="-1.5708 0 0" />
    <parent
      link="Link_05" />
    <child
      link="Link_06" />
    <axis
      xyz="0 0 1" />
    <limit
      lower="-6.28"
      upper="6.28"
      effort="500"
      velocity="3.14" />
  </joint>

  <transmission name="trans_joint_1">
    <type>transmission_interface/SimpleTransmission</type>
    <joint name="joint_1">
      <hardwareInterface>hardware_interface/PositionJointInterface</hardwareInterface>
    </joint>
    <actuator name="joint_1_motor">
      <hardwareInterface>hardware_interface/PositionJointInterface</hardwareInterface>
      <mechanicalReduction>1</mechanicalReduction>
    </actuator>
  </transmission>
  <transmission name="trans_joint_2">
    <type>transmission_interface/SimpleTransmission</type>
    <joint name="joint_2">
      <hardwareInterface>hardware_interface/PositionJointInterface</hardwareInterface>
    </joint>
    <actuator name="joint_2_motor">
      <hardwareInterface>hardware_interface/PositionJointInterface</hardwareInterface>
      <mechanicalReduction>1</mechanicalReduction>
    </actuator>
  </transmission>
  <transmission name="trans_joint_3">
    <type>transmission_interface/SimpleTransmission</type>
    <joint name="joint_3">
      <hardwareInterface>hardware_interface/PositionJointInterface</hardwareInterface>
    </joint>
    <actuator name="joint_3_motor">
      <hardwareInterface>hardware_interface/PositionJointInterface</hardwareInterface>
      <mechanicalReduction>1</mechanicalReduction>
    </actuator>
  </transmission>
  <transmission name="trans_joint_4">
    <type>transmission_interface/SimpleTransmission</type>
    <joint name="joint_4">
      <hardwareInterface>hardware_interface/PositionJointInterface</hardwareInterface>
    </joint>
    <actuator name="joint_4_motor">
      <hardwareInterface>hardware_interface/PositionJointInterface</hardwareInterface>
      <mechanicalReduction>1</mechanicalReduction>
    </actuator>
  </transmission>
  <transmission name="trans_joint_5">
    <type>transmission_interface/SimpleTransmission</type>
    <joint name="joint_5">
      <hardwareInterface>hardware_interface/PositionJointInterface</hardwareInterface>
    </joint>
    <actuator name="joint_5_motor">
      <hardwareInterface>hardware_interface/PositionJointInterface</hardwareInterface>
      <mechanicalReduction>1</mechanicalReduction>
    </actuator>
  </transmission>
  <transmission name="trans_joint_6">
    <type>transmission_interface/SimpleTransmission</type>
    <joint name="joint_6">
      <hardwareInterface>hardware_interface/PositionJointInterface</hardwareInterface>
    </joint>
    <actuator name="joint_6_motor">
      <hardwareInterface>hardware_interface/PositionJointInterface</hardwareInterface>
      <mechanicalReduction>1</mechanicalReduction>
    </actuator>
  </transmission>
  <gazebo>
    <!-- <plugin name="gazebo_ros2_control" filename="libgazebo_ros2_control.so"> -->
    <plugin name="ign_ros2_control::IgnitionROS2ControlPlugin" filename="libign_ros2_control-system.so">
      <parameters>$(find jaka_pro18_moveit_config)/config/ros2_controllers.yaml</parameters>
      <robotNamespace>/</robotNamespace>
    </plugin>
  </gazebo>
</robot>
