<?xml version="1.0" encoding="utf-8"?>
<!-- This URDF was automatically created by SolidWorks to URDF Exporter! Originally created by Stephen Brawner (brawner@gmail.com) 
     Commit Version: 1.6.0-4-g7f85cfe  Build Version: 1.6.7995.38578
     For more information, please see http://wiki.ros.org/sw_urdf_exporter -->
<robot
  name="jaka_c12">

  <!-- LINK -->
  <link name="world" />

  <link
    name="base_link">
    <inertial>
      <origin
        xyz="0.001294 -0.00020921 0.02001"
        rpy="0 0 0" />
      <mass
        value="0.80436" />
      <inertia
        ixx="0.0014437"
        ixy="-1.411E-06"
        ixz="3.8789E-06"
        iyy="0.0018819"
        iyz="3.2265E-07"
        izz="0.0031342" />
    </inertial>
    <visual>
      <origin
        xyz="0 0 0"
        rpy="0 0 0" />
      <geometry>
        <mesh
          filename="package://jaka_description/meshes/jaka_c12_meshes/base_link.STL" />
      </geometry>
      <material
        name="">
        <color
          rgba="0.84706 0.84706 0.84706 1" />
      </material>
    </visual>
    <collision>
      <origin
        xyz="0 0 0"
        rpy="0 0 0" />
      <geometry>
        <mesh
          filename="package://jaka_description/meshes/jaka_c12_meshes/base_link.STL" />
      </geometry>
    </collision>
  </link>

  <!-- JOINT -->
  <joint name="fixed" type="fixed">
    <origin xyz="0 0 0.04" rpy="0 0 0" />
    <parent link="world"/>
    <child link="base_link"/>
  </joint>

  <link
    name="Link_01">
    <inertial>
      <origin
        xyz="-1.3532E-07 0.0039698 -0.0033275"
        rpy="0 0 0" />
      <mass
        value="29.677" />
      <inertia
        ixx="0.13784"
        ixy="1.785E-07"
        ixz="-5.8341E-07"
        iyy="0.1346"
        iyz="-0.00028533"
        izz="0.092584" />
    </inertial>
    <visual>
      <origin
        xyz="0 0 0"
        rpy="0 0 0" />
      <geometry>
        <mesh
          filename="package://jaka_description/meshes/jaka_c12_meshes/Link_01.STL" />
      </geometry>
      <material
        name="">
        <color
          rgba="0.84706 0.84706 0.84706 1" />
      </material>
    </visual>
    <collision>
      <origin
        xyz="0 0 0"
        rpy="0 0 0" />
      <geometry>
        <mesh
          filename="package://jaka_description/meshes/jaka_c12_meshes/Link_01.STL" />
      </geometry>
    </collision>
  </link>
  <joint
    name="joint_1"
    type="revolute">
    <origin
      xyz="0 -0.0002479 0.14265"
      rpy="0 0 0" />
    <parent
      link="base_link" />
    <child
      link="Link_01" />
    <axis
      xyz="0 0 1" />
    <limit
      lower="-6.28"
      upper="6.28"
      effort="2000"
      velocity="2.09" />
  </joint>
  <link
    name="Link_02">
    <inertial>
      <origin
        xyz="0.2975 -2.0178E-09 -0.17962"
        rpy="0 0 0" />
      <mass
        value="97.715" />
      <inertia
        ixx="0.34047"
        ixy="-1.8174E-06"
        ixz="6.2096E-07"
        iyy="6.1206"
        iyz="-1.091E-07"
        izz="6.0299" />
    </inertial>
    <visual>
      <origin
        xyz="0 0 0"
        rpy="0 0 0" />
      <geometry>
        <mesh
          filename="package://jaka_description/meshes/jaka_c12_meshes/Link_02.STL" />
      </geometry>
      <material
        name="">
        <color
          rgba="0.84706 0.84706 0.84706 1" />
      </material>
    </visual>
    <collision>
      <origin
        xyz="0 0 0"
        rpy="0 0 0" />
      <geometry>
        <mesh
          filename="package://jaka_description/meshes/jaka_c12_meshes/Link_02.STL" />
      </geometry>
    </collision>
  </link>
  <joint
    name="joint_2"
    type="revolute">
    <origin
      xyz="0 0 0"
      rpy="1.5708 0 0" />
    <parent
      link="Link_01" />
    <child
      link="Link_02" />
    <axis
      xyz="0 0 1" />
    <limit
      lower="-1.48"
      upper="4.62"
      effort="8000"
      velocity="2.09" />
  </joint>
  <link
    name="Link_03">
    <inertial>
      <origin
        xyz="0.27266 7.7001E-07 -0.022619"
        rpy="0 0 0" />
      <mass
        value="39.76" />
      <inertia
        ixx="0.056602"
        ixy="1.05E-05"
        ixz="-0.053004"
        iyy="1.7308"
        iyz="1.1887E-06"
        izz="1.7278" />
    </inertial>
    <visual>
      <origin
        xyz="0 0 0"
        rpy="0 0 0" />
      <geometry>
        <mesh
          filename="package://jaka_description/meshes/jaka_c12_meshes/Link_03.STL" />
      </geometry>
      <material
        name="">
        <color
          rgba="0.84706 0.84706 0.84706 1" />
      </material>
    </visual>
    <collision>
      <origin
        xyz="0 0 0"
        rpy="0 0 0" />
      <geometry>
        <mesh
          filename="package://jaka_description/meshes/jaka_c12_meshes/Link_03.STL" />
      </geometry>
    </collision>
  </link>
  <joint
    name="joint_3"
    type="revolute">
    <origin
      xyz="0.595 0 0"
      rpy="0 0 0" />
    <parent
      link="Link_02" />
    <child
      link="Link_03" />
    <axis
      xyz="0 0 1" />
    <limit
      lower="-3.05"
      upper="3.05"
      effort="8000"
      velocity="2.09" />
  </joint>
  <link
    name="Link_04">
    <inertial>
      <origin
        xyz="4.7026E-07 -0.0033901 0.0032626"
        rpy="0 0 0" />
      <mass
        value="6.9371" />
      <inertia
        ixx="0.012274"
        ixy="7.3536E-09"
        ixz="-1.3879E-08"
        iyy="0.0082648"
        iyz="-7.0886E-05"
        izz="0.011813" />
    </inertial>
    <visual>
      <origin
        xyz="0 0 0"
        rpy="0 0 0" />
      <geometry>
        <mesh
          filename="package://jaka_description/meshes/jaka_c12_meshes/Link_04.STL" />
      </geometry>
      <material
        name="">
        <color
          rgba="0.84706 0.84706 0.84706 1" />
      </material>
    </visual>
    <collision>
      <origin
        xyz="0 0 0"
        rpy="0 0 0" />
      <geometry>
        <mesh
          filename="package://jaka_description/meshes/jaka_c12_meshes/Link_04.STL" />
      </geometry>
    </collision>
  </link>
  <joint
    name="joint_4"
    type="revolute">
    <origin
      xyz="0.5715 0 -0.1315"
      rpy="0 0 0" />
    <parent
      link="Link_03" />
    <child
      link="Link_04" />
    <axis
      xyz="0 0 1" />
    <limit
      lower="-1.48"
      upper="4.62"
      effort="2000"
      velocity="2.62" />
  </joint>
  <link
    name="Link_05">
    <inertial>
      <origin
        xyz="-1.8815E-07 -0.0049555 0.0028509"
        rpy="0 0 0" />
      <mass
        value="1.0116" />
      <inertia
        ixx="0.0021783"
        ixy="1.3533E-08"
        ixz="1.3308E-08"
        iyy="0.001186"
        iyz="-1.5031E-05"
        izz="0.0021184" />
    </inertial>
    <visual>
      <origin
        xyz="0 0 0"
        rpy="0 0 0" />
      <geometry>
        <mesh
          filename="package://jaka_description/meshes/jaka_c12_meshes/Link_05.STL" />
      </geometry>
      <material
        name="">
        <color
          rgba="0.79216 0.81961 0.93333 1" />
      </material>
    </visual>
    <collision>
      <origin
        xyz="0 0 0"
        rpy="0 0 0" />
      <geometry>
        <mesh
          filename="package://jaka_description/meshes/jaka_c12_meshes/Link_05.STL" />
      </geometry>
    </collision>
  </link>
  <joint
    name="joint_5"
    type="revolute">
    <origin
      xyz="0 -0.115 0"
      rpy="1.5708 0 -3.1416" />
    <parent
      link="Link_04" />
    <child
      link="Link_05" />
    <axis
      xyz="0 0 -1" />
    <limit
      lower="-6.28"
      upper="6.28"
      effort="3000"
      velocity="2.62" />
  </joint>
  <link
    name="Link_06">
    <inertial>
      <origin
        xyz="-0.00023613 0.00037453 -0.021557"
        rpy="0 0 0" />
      <mass
        value="1.7664" />
      <inertia
        ixx="0.0010745"
        ixy="-6.8627E-07"
        ixz="-6.4908E-07"
        iyy="0.0010759"
        iyz="1.8508E-06"
        izz="0.0017797" />
    </inertial>
    <visual>
      <origin
        xyz="0 0 0"
        rpy="0 0 0" />
      <geometry>
        <mesh
          filename="package://jaka_description/meshes/jaka_c12_meshes/Link_06.STL" />
      </geometry>
      <material
        name="">
        <color
          rgba="0.84706 0.84706 0.84706 1" />
      </material>
    </visual>
    <collision>
      <origin
        xyz="0 0 0"
        rpy="0 0 0" />
      <geometry>
        <mesh
          filename="package://jaka_description/meshes/jaka_c12_meshes/Link_06.STL" />
      </geometry>
    </collision>
  </link>
  <joint
    name="joint_6"
    type="revolute">
    <origin
      xyz="-0.00025841 0.1035 -0.00025841"
      rpy="1.5708 0 3.1416" />
    <parent
      link="Link_05" />
    <child
      link="Link_06" />
    <axis
      xyz="0 0 1" />
    <limit
      lower="-6.28"
      upper="6.28"
      effort="1000"
      velocity="2.62" />
  </joint>

  <transmission name="trans_joint_1">
        <type>transmission_interface/SimpleTransmission</type>
        <joint name="joint_1">
            <hardwareInterface>hardware_interface/PositionJointInterface</hardwareInterface>
        </joint>
        <actuator name="joint_1_motor">
            <hardwareInterface>hardware_interface/PositionJointInterface</hardwareInterface>
            <mechanicalReduction>1</mechanicalReduction>
        </actuator>
    </transmission>
    <transmission name="trans_joint_2">
        <type>transmission_interface/SimpleTransmission</type>
        <joint name="joint_2">
            <hardwareInterface>hardware_interface/PositionJointInterface</hardwareInterface>
        </joint>
        <actuator name="joint_2_motor">
            <hardwareInterface>hardware_interface/PositionJointInterface</hardwareInterface>
            <mechanicalReduction>1</mechanicalReduction>
        </actuator>
    </transmission>
    <transmission name="trans_joint_3">
        <type>transmission_interface/SimpleTransmission</type>
        <joint name="joint_3">
            <hardwareInterface>hardware_interface/PositionJointInterface</hardwareInterface>
        </joint>
        <actuator name="joint_3_motor">
            <hardwareInterface>hardware_interface/PositionJointInterface</hardwareInterface>
            <mechanicalReduction>1</mechanicalReduction>
        </actuator>
    </transmission>
    <transmission name="trans_joint_4">
        <type>transmission_interface/SimpleTransmission</type>
        <joint name="joint_4">
            <hardwareInterface>hardware_interface/PositionJointInterface</hardwareInterface>
        </joint>
        <actuator name="joint_4_motor">
            <hardwareInterface>hardware_interface/PositionJointInterface</hardwareInterface>
            <mechanicalReduction>1</mechanicalReduction>
        </actuator>
    </transmission>
    <transmission name="trans_joint_5">
        <type>transmission_interface/SimpleTransmission</type>
        <joint name="joint_5">
            <hardwareInterface>hardware_interface/PositionJointInterface</hardwareInterface>
        </joint>
        <actuator name="joint_5_motor">
            <hardwareInterface>hardware_interface/PositionJointInterface</hardwareInterface>
            <mechanicalReduction>1</mechanicalReduction>
        </actuator>
    </transmission>
    <transmission name="trans_joint_6">
        <type>transmission_interface/SimpleTransmission</type>
        <joint name="joint_6">
            <hardwareInterface>hardware_interface/PositionJointInterface</hardwareInterface>
        </joint>
        <actuator name="joint_6_motor">
            <hardwareInterface>hardware_interface/PositionJointInterface</hardwareInterface>
            <mechanicalReduction>1</mechanicalReduction>
        </actuator>
    </transmission>
    <gazebo>
        <!-- <plugin name="gazebo_ros2_control" filename="libgazebo_ros2_control.so"> -->
        <plugin name="ign_ros2_control::IgnitionROS2ControlPlugin" filename="libign_ros2_control-system.so">
            <parameters>$(find jaka_c12_moveit_config)/config/ros2_controllers.yaml</parameters>
            <robotNamespace>/</robotNamespace>
        </plugin>
    </gazebo>

</robot>